<?xml version="1.0" encoding="UTF-8"?>
<testsuites>
  <testsuite id="0" name="/Users/m0s01ax/Git/hoggle/githoggle/src/movies/activities/content-details-activity.unit.test.ts" errors="0" package="/Users/m0s01ax/Git/hoggle/githoggle/src/movies/activities/content-details-activity.unit.test.ts" hostname="localhost" tests="2" failures="1" time="0.921" timestamp="2018-01-15T20:19:30">
    <properties>
    </properties>
    <testcase classname="ContentDetailsFetch" name="should call the dao once" time="0">
    </testcase>
    <testcase classname="ContentDetailsFetch" name="should match the content id" time="0">
      <failure message="Error: [2mexpect([22m[31mjest.fn()[39m[2m).toHaveBeenCalledTimes([22m[32m20[39m[2m)[22m

Expected mock function to have been called [32m20 times[39m, but it was called [31mone time[39m.
    at Object.&lt;anonymous&gt; (/Users/m0s01ax/Git/hoggle/githoggle/src/movies/activities/content-details-activity.unit.test.ts:76:44)
    at resolve (/Users/m0s01ax/Git/hoggle/githoggle/node_modules/jest-jasmine2/build/queue_runner.js:51:12)
    at new Promise (&lt;anonymous&gt;)
    at mapper (/Users/m0s01ax/Git/hoggle/githoggle/node_modules/jest-jasmine2/build/queue_runner.js:40:274)
    at promise.then (/Users/m0s01ax/Git/hoggle/githoggle/node_modules/jest-jasmine2/build/queue_runner.js:83:39)
    at &lt;anonymous&gt;
    at process._tickCallback (internal/process/next_tick.js:160:7)" type="AssertionError">
      </failure>
    </testcase>
    <system-out/>
    <system-err/>
  </testsuite>
  <testsuite id="1" name="/Users/m0s01ax/Git/hoggle/githoggle/src/util/optional.unit.test.ts" errors="0" package="/Users/m0s01ax/Git/hoggle/githoggle/src/util/optional.unit.test.ts" hostname="localhost" tests="1" failures="0" time="0.017" timestamp="2018-01-15T20:19:30">
    <properties>
    </properties>
    <testcase classname="Optional" name="should be absent when it&apos;s absent" time="0">
    </testcase>
    <system-out/>
    <system-err/>
  </testsuite>
</testsuites>